Workbook

Sheet Data
A1: Rawafid Trading Co. - Odoo balances, FY 2026
A2: Source: Odoo reports as of 31/12/2026 (Balance Sheet, Profit and Loss). SAR. Blue = typed from Odoo.
A4: Account | B4: Name | C4: Balance (SAR) | D4: Group | F4: Group | G4: Total (SAR)
A5: 101001 | B5: Bank | C5: 715368.46 | D5: Cash | F5: Cash | G5: =SUMIFS($C$5:$C$51,$D$5:$D$51,"Cash") -> 780218.46
A6: 101007 | B6: Bank Albilad | C6: 64850 | D6: Cash | F6: Receivables | G6: =SUMIFS($C$5:$C$51,$D$5:$D$51,"Receivables") -> 404225
A7: 102011 | B7: Accounts receivable | C7: 412850 | D7: Receivables | F7: Inventory | G7: =SUMIFS($C$5:$C$51,$D$5:$D$51,"Inventory") -> 232011
A8: 102017 | B8: Provision for doubtful receivables | C8: -8625 | D8: Receivables | F8: VAT recoverable | G8: =SUMIFS($C$5:$C$51,$D$5:$D$51,"VAT recoverable") -> 355581.04
A9: 100202 | B9: Inventory | C9: 232011 | D9: Inventory | F9: Prepayments | G9: =SUMIFS($C$5:$C$51,$D$5:$D$51,"Prepayments") -> 6000
A10: 101060 | B10: VAT paid at customs | C10: 22500 | D10: VAT recoverable | F10: Fixed assets | G10: =SUMIFS($C$5:$C$51,$D$5:$D$51,"Fixed assets") -> 318838.9
A11: 104041 | B11: Input VAT | C11: 332541.04 | D11: VAT recoverable | F11: Payables | G11: =SUMIFS($C$5:$C$51,$D$5:$D$51,"Payables") -> 410071.9
A12: 104043 | B12: Input VAT (other) | C12: 540 | D12: VAT recoverable | F12: Output VAT | G12: =SUMIFS($C$5:$C$51,$D$5:$D$51,"Output VAT") -> 357540
A13: 104024 | B13: Prepaid insurance | C13: 6000 | D13: Prepayments | F13: Zakat payable | G13: =SUMIFS($C$5:$C$51,$D$5:$D$51,"Zakat payable") -> 26267.85
A14: 100107 | B14: Machinery and tools | C14: 68000 | D14: Fixed assets | F14: Capital | G14: =SUMIFS($C$5:$C$51,$D$5:$D$51,"Capital") -> 1000000
A15: 100108 | B15: Furniture and equipment | C15: 15000 | D15: Fixed assets | F15: Sales | G15: =SUMIFS($C$5:$C$51,$D$5:$D$51,"Sales") -> 9221000
A16: 100110 | B16: Vehicles | C16: 255000 | D16: Fixed assets | F16: Other revenue | G16: =SUMIFS($C$5:$C$51,$D$5:$D$51,"Other revenue") -> 24000
A17: 102020 | B17: Acc. depreciation - vehicles | C17: -16049.99 | D17: Fixed assets | F17: COGS | G17: =SUMIFS($C$5:$C$51,$D$5:$D$51,"COGS") -> 7334000
A18: 102021 | B18: Acc. depreciation - machinery | C18: -2219.44 | D18: Fixed assets | F18: Salaries | G18: =SUMIFS($C$5:$C$51,$D$5:$D$51,"Salaries") -> 1110450
A19: 102022 | B19: Acc. depreciation - furniture | C19: -891.67 | D19: Fixed assets | F19: GOSI | G19: =SUMIFS($C$5:$C$51,$D$5:$D$51,"GOSI") -> 96926.4
A20: 201002 | B20: Accounts payable | C20: 395600 | D20: Payables | F20: Rent | G20: =SUMIFS($C$5:$C$51,$D$5:$D$51,"Rent") -> 166000
A21: 201022 | B21: GOSI payable | C21: 14471.9 | D21: Payables | F21: Utilities | G21: =SUMIFS($C$5:$C$51,$D$5:$D$51,"Utilities") -> 48000
A22: 201017 | B22: Output VAT | C22: 357540 | D22: Output VAT | F22: Insurance | G22: =SUMIFS($C$5:$C$51,$D$5:$D$51,"Insurance") -> 37000
A23: 201040 | B23: Zakat payable | C23: 26267.85 | D23: Zakat payable | F23: Vehicle rental | G23: =SUMIFS($C$5:$C$51,$D$5:$D$51,"Vehicle rental") -> 87500
A24: 300001 | B24: Share capital | C24: 1000000 | D24: Capital | F24: Other opex | G24: =SUMIFS($C$5:$C$51,$D$5:$D$51,"Other opex") -> 11845
A25: 500001 | B25: Product sales | C25: 9221000 | D25: Sales | F25: Non-recurring | G25: =SUMIFS($C$5:$C$51,$D$5:$D$51,"Non-recurring") -> 15625
A26: 500007 | B26: Rental income | C26: 24000 | D26: Other revenue | F26: Zakat | G26: =SUMIFS($C$5:$C$51,$D$5:$D$51,"Zakat") -> 26267.85
A27: 500099 | B27: Cost of goods sold | C27: 7334000 | D27: COGS | F27: Other income | G27: =SUMIFS($C$5:$C$51,$D$5:$D$51,"Other income") -> 2770
A28: 400003 | B28: Basic salary | C28: 805500 | D28: Salaries | F28: Gain on disposal | G28: =SUMIFS($C$5:$C$51,$D$5:$D$51,"Gain on disposal") -> 8240
A29: 400004 | B29: Housing allowance | C29: 201750 | D29: Salaries | F29: Depreciation | G29: =SUMIFS($C$5:$C$51,$D$5:$D$51,"Depreciation") -> 19401.1
A30: 400005 | B30: Transport allowance | C30: 52800 | D30: Salaries
A31: 400012 | B31: Other allowances | C31: 50400 | D31: Salaries | F31: Total assets | G31: =SUM(G5:G10) -> 2096874.4
A32: 400010 | B32: GOSI employer share | C32: 96926.4 | D32: GOSI | F32: Total liabilities | G32: =SUM(G11:G13) -> 793879.75
A33: 400017 | B33: Warehouse rent | C33: 166000 | D33: Rent | F33: Net profit | G33: =Data!$G$15+Data!$G$16+Data!$G$27+Data!$G$28-Data!$G$17-SUM(G18:G26)-Data!$G$29 -> 302994.65
A34: 400018 | B34: Water and electricity | C34: 48000 | D34: Utilities | F34: Check: A - L - E (should be 0) | G34: =ROUND(Data!$G$31-Data!$G$32-Data!$G$14-Data!$G$33,2) -> 0
A35: 400040 | B35: Insurance | C35: 37000 | D35: Insurance
A36: 400074 | B36: Vehicle rental | C36: 87500 | D36: Vehicle rental
A37: 400006 | B37: Exit/re-entry tickets | C37: 120 | D37: Other opex
A38: 400023 | B38: Communication | C38: 8400 | D38: Other opex
A39: 400034 | B39: Advertising | C39: 800 | D39: Other opex
A40: 400051 | B40: Bank charges | C40: 150 | D40: Other opex
A41: 400091 | B41: Other employee expenses | C41: 500 | D41: Other opex
...

Sheet Ratios
F4: Helper | G4: SAR
A5: Liquidity | F5: Revenue | G5: =Data!$G$15+Data!$G$16 -> 9245000
A6: Current ratio | B6: =(Data!$G$31-Data!$G$10)/Data!$G$32 -> 2.2396786 | C6: Current assets / current liabilities | D6: Comfortable | F6: Gross profit | G6: =G5-Data!$G$17 -> 1911000
A7: Quick ratio | B7: =(Data!$G$5+Data!$G$6)/Data!$G$32 -> 1.4919683 | C7: (Cash + net receivables) / current liabilities | D7: Strong | F7: Operating expenses excl. zakat | G7: =SUM(Data!$G$18:$G$25) -> 1573346.4
A8: Cash ratio | B8: =Data!$G$5/Data!$G$32 -> 0.98279174 | C8: Cash / current liabilities | D8: Cash covers almost all short-term debts | F8: Operating income before zakat | G8: =G6-G7 -> 337653.6
A9: Profitability | F9: Gross receivables | G9: =Data!$C$7 -> 412850
A10: Gross profit margin | B10: =(Data!$G$15+Data!$G$16-Data!$G$17)/(Data!$G$15+Data!$G$16) -> 0.20670633 | C10: Gross profit / revenue | D10: Normal for building materials trading
A11: Operating margin (before zakat) | B11: =G8/G5 -> 0.036522834 | C11: Operating income before zakat / revenue | D11: Thin
A12: Net profit margin | B12: =Data!$G$33/(Data!$G$15+Data!$G$16) -> 0.032773894 | C12: Net profit / revenue | D12: Thin
A13: Operating expenses / gross profit | B13: =G7/G6 -> 0.82331052 | C13: Operating expenses (excl. zakat) / gross profit | D13: High: the main reason margins are thin
A14: Return on assets | B14: =Data!$G$33/Data!$G$31 -> 0.14449824 | C14: Net profit / total assets | D14: Strong
A15: Return on equity | B15: =Data!$G$33/(Data!$G$14+Data!$G$33) -> 0.23253714 | C15: Net profit / equity | D15: Strong for a first year
A16: Activity
A17: Asset turnover | B17: =(Data!$G$15+Data!$G$16)/Data!$G$31 -> 4.4089431 | C17: Revenue / total assets | D17: Assets are used intensively
A18: Receivables turnover | B18: =Data!$G$15/G9 -> 22.334988 | C18: Product sales / gross receivables | D18: Uses total sales; cash sales flatter it
A19: Days sales outstanding | B19: =365/B18 -> 16.342072 | C19: 365 / receivables turnover | D19: Conflicts with the aging report (see review notes)
A20: Leverage
A21: Debt ratio | B21: =Data!$G$32/Data!$G$31 -> 0.37860148 | C21: Liabilities / total assets | D21: Conservative
A22: Liabilities to equity | B22: =Data!$G$32/(Data!$G$14+Data!$G$33) -> 0.60927322 | C22: Liabilities / equity | D22: Safe
A24: Conclusion: liquidity and leverage are healthy; profitability is the weak point because operating expenses absorb most of gross profit.

Sheet Cash Flow
A1: Statement of cash flows - indirect method, FY 2026
A2: Built from the year-end balance sheet; all opening balances are zero (first year).
A4: Line | B4: SAR | C4: Source
A5: Operating activities
A6: Net profit | B6: =Data!$G$33 -> 302994.65 | C6: Income statement
A7: Depreciation | B7: =Data!$G$29 -> 19401.1 | C7: Non-cash
A8: Loss on asset revaluation | B8: =Data!$C$44 -> 7000 | C8: Non-cash
A9: Gain on asset disposal | B9: =-Data!$G$28 -> -8240 | C9: Proceeds shown under investing
A10: Doubtful debts provision | B10: =Data!$C$43 -> 8625 | C10: Non-cash
A11: Zakat accrued, unpaid | B11: =Data!$G$13 -> 26267.85 | C11: Non-cash until paid
A12: Increase in receivables (gross) | B12: =-Data!$C$7 -> -412850 | C12: Working capital
A13: Increase in inventory | B13: =-Data!$G$7 -> -232011 | C13: Working capital
A14: Increase in VAT recoverable | B14: =-Data!$G$8 -> -355581.04 | C14: Working capital
A15: Increase in prepayments | B15: =-Data!$G$9 -> -6000 | C15: Working capital
A16: Increase in payables (incl. GOSI) | B16: =Data!$G$11 -> 410071.9 | C16: Working capital
A17: Increase in output VAT | B17: =Data!$G$12 -> 357540 | C17: Working capital
A18: Net cash from operating activities | B18: =SUM(B6:B17) -> 117218.46
A19: Investing activities
A20: Purchase of fixed assets | B20: -468000 | C20: Odoo cash flow report: 75,000 + 15,000 + 378,000
A21: Proceeds from asset disposal | B21: 131000 | C21: Odoo cash flow report: 116,000 + 15,000
A22: Net cash used in investing activities | B22: =SUM(B20:B21) -> -337000
A23: Financing activities
A24: Share capital paid in | B24: =Data!$G$14 -> 1000000 | C24: Account 300001
A25: Net cash from financing activities | B25: =B24 -> 1000000
A26: Net increase in cash | B26: =B18+B22+B25 -> 780218.46
A27: Cash at 1 January 2026 | B27: 0 | C27: First year
A28: Cash at 31 December 2026 | B28: =B26+B27 -> 780218.46
A29: Cash per balance sheet | B29: =Data!$G$5 -> 780218.46 | C29: Accounts 101001 + 101007
A30: Difference (should be 0) | B30: =ROUND(B28-B29,2) -> 0
A33: Fixed asset roll-forward check: purchases - revaluation loss - NBV of disposal - depreciation = net fixed assets
A34: NBV of vehicle disposed (proceeds - gain) | B34: =B21-Data!$G$28 -> 122760
A35: Net fixed assets (roll-forward) | B35: =-B20-Data!$C$44-B34-Data!$G$29 -> 318838.9
A36: Net fixed assets per balance sheet | B36: =Data!$G$10 -> 318838.9
A37: Difference (should be 0) | B37: =ROUND(B35-B36,2) -> 0

Sheet Zakat
A1: Zakat calculation - FY 2026
A2: Simplified base for a trading company (ZATCA rules govern the full calculation).
A4: Item | B4: SAR | C4: Note
A5: Share capital | B5: =Data!$G$14 -> 1000000 | C5: Added
A6: Profit before zakat | B6: =Data!$G$33+Data!$G$26 -> 329262.5 | C6: Added
A7: Doubtful debts provision | B7: =-Data!$C$8 -> 8625 | C7: Added: provisions are part of the base
A8: Net fixed assets | B8: =-Data!$G$10 -> -318838.9 | C8: Deducted
A9: Zakat base | B9: =SUM(B5:B8) -> 1019048.6 | C9: Base is never below profit before zakat
A10: Zakat rate (Gregorian year) | B10: 0.025775 | C10: 2.5% x 365/354
A11: Zakat due | B11: =MAX(B9,B6)*B10 -> 26265.978
A12: Zakat booked in Odoo | B12: =Data!$G$26 -> 26267.85 | C12: Account 400072 / 201040
A13: Difference | B13: =ROUND(B12-B11,2) -> 1.87 | C13: Small difference to review against the booked entry

Sheet Break-even
A1: Break-even model - monthly, based on FY 2026 actuals
A2: Fixed costs = annual Odoo totals / 12. Variable cost ratio = COGS / product sales from the books.
A4: Monthly fixed costs | B4: SAR / month | C4: Source
A5: Salaries and allowances | B5: =Data!$G$18/12 -> 92537.5 | C5: 400003+400004+400005+400012
A6: Employer GOSI | B6: =Data!$G$19/12 -> 8077.2 | C6: 400010
A7: Warehouse rent | B7: =Data!$G$20/12 -> 13833.333 | C7: 400017
A8: Water and electricity | B8: =Data!$G$21/12 -> 4000 | C8: 400018
A9: Insurance | B9: =Data!$G$22/12 -> 3083.3333 | C9: 400040
A10: Vehicle rental | B10: =Data!$G$23/12 -> 7291.6667 | C10: 400074
A11: Other expenses | B11: =Data!$G$24/12 -> 987.08333 | C11: 400006, 400023, 400034, 400051, 400091, 400099
A12: Depreciation (full monthly charge) | B12: 5375 | C12: Asset register: straight line, 5 and 10 years
A13: Total fixed costs | B13: =SUM(B5:B12) -> 135185.12
A15: Drivers | B15: Value | C15: Source
A16: Variable cost ratio (COGS / product sales) | B16: =Data!$G$17/Data!$G$15 -> 0.79535842 | C16: Books: 7,334,000 / 9,221,000
A17: Scenario variable cost ratio | B17: =B16 -> 0.79535842 | C17: Key lever: overwrite to test a scenario (default = books)
A18: Average monthly product sales | B18: =Data!$G$15/12 -> 768416.67
A20: Results | B20: Value
A21: Contribution margin ratio | B21: =1-B17 -> 0.20464158
A22: Break-even sales (SAR / month) | B22: =IF(B21=0,0,B13/B21) -> 660594.57
A23: Margin of safety (SAR) | B23: =B18-B22 -> 107822.09
A24: Margin of safety (%) | B24: =IF(B18=0,0,B23/B18) -> 0.14031722
A25: Monthly operating profit (loss) | B25: =B18*B21-B13 -> 22064.883
A26: Status | B26: =IF(B25>0,"Profit",IF(B25=0,"Break-even","Loss")) -> Profit
A28: Sensitivity: monthly profit (loss) by variable cost ratio
A29: Variable cost ratio | B29: 0.75 | C29: 0.78 | D29: =B16 -> 0.79535842 | E29: 0.8 | F29: 0.82 | G29: 0.85
A30: Monthly profit (loss) | B30: =$B$18*(1-B29)-$B$13 -> 56919.05 | C30: =$B$18*(1-C29)-$B$13 -> 33866.55 | D30: =$B$18*(1-D29)-$B$13 -> 22064.883 | E30: =$B$18*(1-E29)-$B$13 -> 18498.217 | F30: =$B$18*(1-F29)-$B$13 -> 3129.8833 | G30: =$B$18*(1-G29)-$B$13 -> -19922.617
A31: Variable cost ratio at which monthly profit is zero | B31: =1-B13/B18 -> 0.82407316
A32: About three points of extra purchase cost (79.5% to 82.4%) wipe out the monthly profit.
A34: Chart data
A35: Monthly sales | B35: Revenue | C35: Fixed costs | D35: Total costs
A36: 0 | B36: =A36 -> 0 | C36: =$B$13 -> 135185.12 | D36: =$B$13+A36*$B$17 -> 135185.12
A37: 100000 | B37: =A37 -> 100000 | C37: =$B$13 -> 135185.12 | D37: =$B$13+A37*$B$17 -> 214720.96
A38: 200000 | B38: =A38 -> 200000 | C38: =$B$13 -> 135185.12 | D38: =$B$13+A38*$B$17 -> 294256.8
A39: 300000 | B39: =A39 -> 300000 | C39: =$B$13 -> 135185.12 | D39: =$B$13+A39*$B$17 -> 373792.64
A40: 400000 | B40: =A40 -> 400000 | C40: =$B$13 -> 135185.12 | D40: =$B$13+A40*$B$17 -> 453328.49
A41: 500000 | B41: =A41 -> 500000 | C41: =$B$13 -> 135185.12 | D41: =$B$13+A41*$B$17 -> 532864.33
A42: 600000 | B42: =A42 -> 600000 | C42: =$B$13 -> 135185.12 | D42: =$B$13+A42*$B$17 -> 612400.17
A43: 700000 | B43: =A43 -> 700000 | C43: =$B$13 -> 135185.12 | D43: =$B$13+A43*$B$17 -> 691936.01
A44: 800000 | B44: =A44 -> 800000 | C44: =$B$13 -> 135185.12 | D44: =$B$13+A44*$B$17 -> 771471.85
A45: 900000 | B45: =A45 -> 900000 | C45: =$B$13 -> 135185.12 | D45: =$B$13+A45*$B$17 -> 851007.7

Sheet Reconciliation
A1: Model to books reconciliation - FY 2026
A2: Proves the break-even model rebuilds the operating income Odoo reports.
A4: Item | B4: SAR | C4: Explanation
A5: Model operating profit x 12 | B5: ='Break-even'!B18*12*(1-'Break-even'!B16)-'Break-even'!B13*12 -> 264778.6 | C5: At the books variable cost ratio
A6: + Rental income | B6: =Data!$G$16 -> 24000 | C6: Revenue outside product sales
A7: + Full depreciation in the model | B7: ='Break-even'!B12*12 -> 64500 | C7: Odoo books depreciation below operating income
A8: - Doubtful debts expense | B8: =-Data!$C$43 -> -8625 | C8: In Odoo operating expenses, non-recurring
A9: - Loss on asset revaluation | B9: =-Data!$C$44 -> -7000 | C9: In Odoo operating expenses, non-recurring
A10: - Zakat expense | B10: =-Data!$G$26 -> -26267.85 | C10: In Odoo operating expenses
A11: Operating income per the model | B11: =SUM(B5:B10) -> 311385.75
A12: Operating income per Odoo | B12: 311385.75 | C12: Profit and Loss report, 2026
A13: Difference (should be 0) | B13: =ROUND(B11-B12,2) -> 0
